Workbook
Name _Hlk139903454: '<35K'!$I$22
Name _Hlk139903454: Master!$I$25

Sheet Master
A1: BSD Technologies - Master | E1: 43951 | H1: HIDE | J1: Forex | K1: 276 | Q1: HIDE | R1: HIDE | S1: HIDE | T1: HIDE | AG1: 2000
A2: Payroll
A3: Wkg Days (Local) | G3: 19 | AJ3: 1.1666667
A4: Wkg Days (Hardware UK) | G4: 20 | Q4: =COLUMN()-2 -> 15 | R4: =COLUMN()-2 -> 16 | S4: =COLUMN()-2 -> 17 | T4: =COLUMN()-2 -> 18 | AJ4: =COLUMN()-2 -> 34 | AK4: =COLUMN()-2 -> 35 | AL4: =COLUMN()-2 -> 36 | BF4: =COLUMN()-2 -> 56
A5: Wkg Days (Design US) | G5: 21 | AW5: DISBURSEMENT DETAIL
A6: Wkg Days (Hardware US) | G6: 21 | J6: =COLUMN()-5 -> 5 | K6: =COLUMN()-5 -> 6 | M6: =COLUMN()-5 -> 8 | N6: =COLUMN()-5 -> 9 | O6: =COLUMN()-5 -> 10 | P6: =COLUMN()-5 -> 11 | Q6: =COLUMN()-5 -> 12 | R6: =COLUMN()-5 -> 13 | S6: =COLUMN()-5 -> 14 | T6: =COLUMN()-5 -> 15 | ... AL6: =COLUMN()-5 -> 33 | AW6: =+AW56 -> 106789 | AX6: =+AX56 -> 44461 | BC6: =SUM(AW6:BB6) -> 151250
B7: Sr.No | C7: date of last increment | D7: last incremnet | E7: # Months Since Last Increment | F7: Emp Code | G7: DOJ (DD/MM/Y) | H7: CURRENT STATUS | I7: Employee Name (CNIC) | J7: Department | K7: Designation | L7: Reporting Manager | M7: MCS | N7: BRAND | O7: Status | P7: Gross Salary | Q7: Basic Salary | R7: H.Rent All | S7: Ut. All | T7: Conv. All | U7: Gross salary with Conveyance | V7: Bonus/Incentive/ Reimbursemet | W7: No.Extra Days | X7: Amount Ex. Days | Y7: DISAPPROVED Absent Days | Z7: Deduction absent Days | AA7: Hourly Rate | AB7: No. of Ded Hours | AC7: Ded Amt Hrs | AD7: Net Gross | AE7: Tax | AF7: EOBI | AG7: Advance | AH7: Loan | AI7: Net Pay | AJ7: Bank Name | AK7: AC Number | AL7: CNIC | AM7: Account Title | AN7: HBL | AO7: Samba | AP7: Cheque | AQ7: IBFT | AR7: Cash | AS7: Payments | AT7: Hold | AU7: Total | AV7: Payment Status | AW7: 1st Batch HBL to HBL 08 May 2024 | AX7: 2nd Batch IBFT 08 May 2024 | AY7: 3rd Batch Cash 08 May 2024 | AZ7: 4th Batch HBL to HBL 10 May 2022 | BA7: 5th Batch IBFT 10 May 2022 | BB7: Column4 | BC7: On Hold | BD7: Total3 | BE7: Difference | BF7: Region | BG7: EOBI Employers' Contribution
B8: 49 | F8: 701 | G8: 43684 | H8: CT | I8: Usman Amin | J8: Sales | K8: International Sales Executive | L8: Umer Shahjahan | M8: HW | N8: BNS | O8: NP | P8: =85000*0 -> 0 | Q8: =P8/160% -> 0 | R8: =40/100*Q8 -> 0 | S8: =10/100*Q8 -> 0 | T8: =10/100*Q8 -> 0 | U8: =Q8+R8+S8+T8 -> 0 | X8: =P8/$G$6*W8 -> 0 | Y8: 0 | Z8: =P8/$G$6*Y8 -> 0 | AA8: =P8/$G$6/9 -> 0 | AC8: =AA8*AB8 -> 0 | AD8: =U8+V8+X8-Z8-AC8 -> 0 | AE8: 0 | AF8: 0 | AG8: 0 | AH8: 0 | AI8: =AD8-AE8-AG8-AH8-AF8 -> 0 | AJ8: Habib Bank Limited | AK8: 0445-79012790-99 | AL8: 35202-7785641-9 | AM8: Muhammad ADA | AN8: =AI8 -> 0 | AS8: =SUM(AN8:AR8) -> 0 | AU8: =+AS8+AT8 -> 0 | AV8: =+AI8-AU8 -> 0 | AZ8: 0 | BA8: 0 | BD8: =SUM(AW8:BC8) -> 0 | BE8: =BD8-AU8 -> 0 | BF8: US | BG8: =AF8/1*5 -> 0
B9: 15 | F9: 191 | G9: 43788 | H9: NJ | I9: Usman | J9: Data Analysis | K9: Trainee | L9: Azmeer | M9: HW | N9: ALL | O9: NP | P9: 15000 | Q9: =P9/160% -> 9375 | R9: =40/100*Q9 -> 3750 | S9: =10/100*Q9 -> 937.5 | T9: =10/100*Q9 -> 937.5 | U9: =Q9+R9+S9+T9 -> 15000 | X9: =P9/$G$3*W9 -> 0 | Y9: 14 | Z9: =P9/$G$3*Y9 -> 11052.632 | AA9: =P9/$G$3/9 -> 87.719298 | AC9: =AA9*AB9 -> 0 | AD9: =U9+V9+X9-Z9-AC9 -> 3947.3684 | AE9: 0 | AF9: 0 | AG9: 0 | AH9: 0 | AI9: =AD9-AE9-AG9-AH9-AF9 -> 3947.3684 | AM9: Muhammad Khawar | AR9: =Master[[#This Row],[Net Pay]] -> 3947.3684 | AS9: =SUM(AN9:AR9) -> 3947.3684 | AU9: =+AS9+AT9 -> 3947.3684 | AV9: Paid | AY9: 3947 | AZ9: 0 | BA9: 0 | BD9: =SUM(AW9:BC9) -> 3947 | BE9: =BD9-AU9 -> -0.36842105 | BF9: Local | BG9: =AF9/1*5 -> 0
F10: 230 | G10: 43945 | I10: Muhammad Yousha | J10: Sales | K10: International Sales Executive | M10: HW | N10: BD | O10: NP | P10: 35000 | Q10: =P10/160% -> 21875 | R10: =40/100*Q10 -> 8750 | S10: =10/100*Q10 -> 2187.5 | T10: =10/100*Q10 -> 2187.5 | U10: =Q10+R10+S10+T10 -> 35000 | X10: =P10/$G$4*W10 -> 0 | Y10: 17 | Z10: =P10/$G$4*Y10 -> 29750 | AA10: =P10/$G$4/9 -> 194.44444 | AC10: =AA10*AB10 -> 0 | AD10: =U10+V10+X10-Z10-AC10 -> 5250 | AE10: 0 | AG10: 0 | AH10: 0 | AI10: =AD10-AE10-AG10-AH10-AF10 -> 5250 | AJ10: Meezan Bank Limited | AK10: PK08MEZN0001130105931538 | AL10: 42301-6418406-5 | AM10: Muhammad Yousha | AQ10: =Master[[#This Row],[Net Pay]] -> 5250 | AS10: =SUM(AN10:AR10) -> 5250 | AU10: =+AS10+AT10 -> 5250 | AV10: Paid | AX10: 5250 | AZ10: 0 | BD10: =SUM(AW10:BC10) -> 5250 | BE10: =BD10-AU10 -> 0 | BF10: UK | BG10: =AF10/1*5 -> 0
F11: 229 | G11: 43942 | I11: Maham Khan | J11: Sales | K11: International Sales Executive | M11: HW | N11: BD | O11: NP | P11: 30000 | Q11: =P11/160% -> 18750 | R11: =40/100*Q11 -> 7500 | S11: =10/100*Q11 -> 1875 | T11: =10/100*Q11 -> 1875 | U11: =Q11+R11+S11+T11 -> 30000 | X11: =P11/$G$4*W11 -> 0 | Y11: 13 | Z11: =P11/$G$4*Y11 -> 19500 | AA11: =P11/$G$4/9 -> 166.66667 | AC11: =AA11*AB11 -> 0 | AD11: =U11+V11+X11-Z11-AC11 -> 10500 | AE11: 0 | AG11: 0 | AH11: 0 | AI11: =AD11-AE11-AG11-AH11-AF11 -> 10500 | AJ11: Habib Bank Limited | AK11: PK70HABB0022567901806303 | AL11: 42301-1466430-6 | AM11: Muhammad Ali | AR11: =AI11 -> 10500 | AS11: =SUM(AN11:AR11) -> 10500 | AU11: =+AS11+AT11 -> 10500 | AV11: Paid | AY11: 10500 | AZ11: 0 | BA11: 0 | BD11: =SUM(AW11:BC11) -> 10500 | BE11: =BD11-AU11 -> 0 | BF11: UK | BG11: =AF11/1*5 -> 0
F12: 228 | I12: Kashan Ahmed | J12: Marketing - SEO | K12: SEO Intern | L12: Muhammad Yousuf | M12: HW | N12: ALL | O12: NP | P12: 35000 | Q12: =P12/160% -> 21875 | R12: =40/100*Q12 -> 8750 | S12: =10/100*Q12 -> 2187.5 | T12: =10/100*Q12 -> 2187.5 | U12: =Q12+R12+S12+T12 -> 35000 | X12: =P12/$G$3*W12 -> 0 | Y12: 14 | Z12: =P12/$G$3*Y12 -> 25789.474 | AA12: =P12/$G$3/9 -> 204.67836 | AC12: =AA12*AB12 -> 0 | AD12: =U12+V12+X12-Z12-AC12 -> 9210.5263 | AE12: 0 | AH12: 0 | AI12: =AD12-AE12-AG12-AH12-AF12 -> 9210.5263 | AJ12: Faysal Bank Limited | AK12: PK62FAYS3573383000001097 | AM12: Kashan Ahmed | AS12: =SUM(AN12:AR12) -> 0 | AT12: =Master[[#This Row],[Net Pay]] -> 9210.5263 | AU12: =+AS12+AT12 -> 9210.5263 | AV12: =+AI12-AU12 -> 0 | AZ12: 0 | BA12: 0 | BC12: 9211 | BD12: =SUM(AW12:BC12) -> 9211 | BE12: =BD12-AU12 -> 0.47368421 | BF12: Local | BG12: =AF12/1*5 -> 0
B13: 16 | F13: 224 | G13: 43861 | I13: Taha Ahmed | J13: Data Analysis | K13: Trainee | L13: Azmeer | M13: HW | N13: ALL | O13: NP | P13: 15000 | Q13: =P13/160% -> 9375 | R13: =40/100*Q13 -> 3750 | S13: =10/100*Q13 -> 937.5 | T13: =10/100*Q13 -> 937.5 | U13: =Q13+R13+S13+T13 -> 15000 | X13: =P13/$G$3*W13 -> 0 | Z13: =P13/$G$3*Y13 -> 0 | AA13: =P13/$G$3/9 -> 87.719298 | AC13: =AA13*AB13 -> 0 | AD13: =U13+V13+X13-Z13-AC13 -> 15000 | AE13: 0 | AG13: 0 | AH13: 0 | AI13: =AD13-AE13-AG13-AH13-AF13 -> 15000 | AJ13: MCB Bank | AK13: PK27MUCB0006802010077407 | AL13: 42201-9587377-5 | AM13: Zameer Ahmed Usmani | AQ13: =AI13 -> 15000 | AS13: =SUM(AN13:AR13) -> 15000 | AU13: =+AS13+AT13 -> 15000 | AV13: Paid | AX13: 14211 | AZ13: 0 | BA13: 789 | BD13: =SUM(AW13:BC13) -> 15000 | BE13: =BD13-AU13 -> 0 | BF13: Local
B14: 7 | F14: 999 | G14: 43496 | H14: CT | I14: Muhammad Farooq | J14: Administration | K14: Electrician | L14: Mubashir | M14: ALL | N14: ALL | O14: NP | P14: 15000 | Q14: =P14/160% -> 9375 | R14: =40/100*Q14 -> 3750 | S14: =10/100*Q14 -> 937.5 | T14: =10/100*Q14 -> 937.5 | U14: =Q14+R14+S14+T14 -> 15000 | X14: =P14/$G$3*W14 -> 0 | Y14: 0 | Z14: =P14/$G$3*Y14 -> 0 | AA14: =P14/$G$3/9 -> 87.719298 | AC14: =AA14*AB14 -> 0 | AD14: =U14+V14+X14-Z14-AC14 -> 15000 | AE14: 0 | AF14: 0 | AG14: 0 | AH14: 0 | AI14: =AD14-AE14-AG14-AH14-AF14 -> 15000 | AJ14: Standard Chartered Bank | AK14: 01994613601 | AM14: Muhammad Farooq | AQ14: =+AI14 -> 15000 | AS14: =SUM(AN14:AR14) -> 15000 | AU14: =+AS14+AT14 -> 15000 | AZ14: 0 | BA14: 15000 | BD14: =SUM(AW14:BC14) -> 15000 | BE14: =BD14-AU14 -> 0 | BF14: Local | BG14: =AF14/1*5 -> 0
B15: 13 | F15: 221 | G15: 43479 | I15: Abdul Sami Kamali | J15: Data Analysis | K15: Trainee | L15: Azmeer | M15: HW | N15: ALL | O15: NP | P15: 25000 | Q15: =P15/160% -> 15625 | R15: =40/100*Q15 -> 6250 | S15: =10/100*Q15 -> 1562.5 | T15: =10/100*Q15 -> 1562.5 | U15: =Q15+R15+S15+T15 -> 25000 | X15: =P15/$G$3*W15 -> 0 | Y15: =7-7 -> 0 | Z15: =P15/$G$3*Y15 -> 0 | AA15: =P15/$G$3/9 -> 146.19883 | AC15: =AA15*AB15 -> 0 | AD15: =U15+V15+X15-Z15-AC15 -> 25000 | AE15: 0 | AG15: 0 | AH15: 0 | AI15: =AD15-AE15-AG15-AH15-AF15 -> 25000 | AJ15: NAYAPAY | AK15: 03313102701 | AL15: 42000-5277363-3 | AM15: Abdul Sami Kamali | AQ15: =AI15 -> 25000 | AS15: =SUM(AN15:AR15) -> 25000 | AU15: =+AS15+AT15 -> 25000 | AV15: Paid | AX15: 25000 | AZ15: 0 | BD15: =SUM(AW15:BC15) -> 25000 | BE15: =BD15-AU15 -> 0 | BF15: Local | BG15: =AF15/1*5 -> 0
B16: 14 | F16: 225 | G16: 43845 | I16: Aun Zaidi | J16: Data Analysis | K16: Trainee | L16: Azmeer | M16: HW | N16: ALL | O16: NP | P16: =15000+5000 -> 20000 | Q16: =P16/160% -> 12500 | R16: =40/100*Q16 -> 5000 | S16: =10/100*Q16 -> 1250 | T16: =10/100*Q16 -> 1250 | U16: =Q16+R16+S16+T16 -> 20000 | X16: =P16/$G$3*W16 -> 0 | Z16: =P16/$G$3*Y16 -> 0 | AA16: =P16/$G$3/9 -> 116.95906 | AC16: =AA16*AB16 -> 0 | AD16: =U16+V16+X16-Z16-AC16 -> 20000 | AE16: 0 | AG16: 0 | AH16: 0 | AI16: =AD16-AE16-AG16-AH16-AF16 -> 20000 | AJ16: Habib Bank Limited | AK16: 08780017874001 | AL16: 42101-6994069-3 | AM16: SYED AJAZ HUSSAIN ZAIDI | AN16: =AI16 -> 20000 | AS16: =SUM(AN16:AR16) -> 20000 | AU16: =+AS16+AT16 -> 20000 | AV16: Paid | AW16: 15789 | AZ16: 4211 | BA16: 0 | BD16: =SUM(AW16:BC16) -> 20000 | BE16: =BD16-AU16 -> 0 | BF16: Local | BG16: =AF16/1*5 -> 0
B17: 22 | C17: 43890 | D17: 10000 | F17: 202 | G17: 43760 | H17: CT | I17: Muhammad Huzaifa Haleem | J17: Marketing - SEO | K17: SEO Intern | L17: Muhammad Yousuf | M17: HW | N17: ALL | O17: NP | P17: =15000+10000 -> 25000 | Q17: =P17/160% -> 15625 | R17: =40/100*Q17 -> 6250 | S17: =10/100*Q17 -> 1562.5 | T17: =10/100*Q17 -> 1562.5 | U17: =Q17+R17+S17+T17 -> 25000 | X17: =P17/$G$3*W17 -> 0 | Y17: 5 | Z17: =P17/$G$3*Y17 -> 6578.9474 | AA17: =P17/$G$3/9 -> 146.19883 | AB17: 15 | AC17: =AA17*AB17 -> 2192.9825 | AD17: =U17+V17+X17-Z17-AC17 -> 16228.07 | AE17: 0 | AF17: 0 | AG17: 0 | AH17: 0 | AI17: =AD17-AE17-AG17-AH17-AF17 -> 16228.07 | AJ17: NAYAPAY | AK17: 03491838351 | AM17: Muhammad Huzaifa Haleem | AS17: =SUM(AN17:AR17) -> 0 | AT17: =Master[[#This Row],[Net Pay]] -> 16228.07 | AU17: =+AS17+AT17 -> 16228.07 | AV17: =+AI17-AU17 -> 0 | AZ17: 0 | BA17: 0 | BC17: 16228 | BD17: =SUM(AW17:BC17) -> 16228 | BE17: =BD17-AU17 -> -0.070175439 | BF17: Local | BG17: =AF17/1*5 -> 0
B18: 23 | F18: 222 | G18: 43861 | I18: Moin Shaikh | J18: Marketing - SEO | K18: SEO Intern | L18: Muhammad Yousuf | M18: HW | N18: ALL | O18: NP | P18: =15000+5000 -> 20000 | Q18: =P18/160% -> 12500 | R18: =40/100*Q18 -> 5000 | S18: =10/100*Q18 -> 1250 | T18: =10/100*Q18 -> 1250 | U18: =Q18+R18+S18+T18 -> 20000 | X18: =P18/$G$3*W18 -> 0 | Z18: =P18/$G$3*Y18 -> 0 | AA18: =P18/$G$3/9 -> 116.95906 | AC18: =AA18*AB18 -> 0 | AD18: =U18+V18+X18-Z18-AC18 -> 20000 | AE18: 0 | AG18: 0 | AH18: 0 | AI18: =AD18-AE18-AG18-AH18-AF18 -> 20000 | AJ18: Meezan Bank Limited | AK18: PK26MEZN0001430109041892 | AL18: 42101-2622969-7 | AM18: MOHAMMAD MOIN UDDIN | AQ18: =AI18 -> 20000 | AS18: =SUM(AN18:AR18) -> 20000 | AU18: =+AS18+AT18 -> 20000 | AV18: =+AI18-AU18 -> 0 | AZ18: 0 | BA18: =18947+1053 -> 20000 | BD18: =SUM(AW18:BC18) -> 20000 | BE18: =BD18-AU18 -> 0 | BF18: Local
B19: 6 | C19: 43738 | D19: 5000 | E19: =ROUND(_xlfn.DAYS($E$1,C19)/30,0) -> 7 | F19: 144 | G19: Apr 2023 | H19: CT | I19: Salman | J19: Administration | K19: Office Boy | L19: Mubashir | M19: ALL | N19: ALL | O19: P | P19: =20000+5000 -> 25000 | Q19: =P19/160% -> 15625 | R19: =40/100*Q19 -> 6250 | S19: =10/100*Q19 -> 1562.5 | T19: =10/100*Q19 -> 1562.5 | U19: =Q19+R19+S19+T19 -> 25000 | X19: =P19/$G$3*W19 -> 0 | Y19: 0 | Z19: =P19/$G$3*Y19 -> 0 | AA19: =P19/$G$3/9 -> 146.19883 | AC19: =AA19*AB19 -> 0 | AD19: =U19+V19+X19-Z19-AC19 -> 25000 | AE19: 0 | AF19: 0 | AG19: 3000 | AH19: 0 | AI19: =AD19-AE19-AG19-AH19-AF19 -> 22000 | AJ19: Habib Bank Limited | AK19: 0017-79008173-03 | AM19: Amanullah | AR19: =+AI19 -> 22000 | AS19: =SUM(AN19:AR19) -> 22000 | AU19: =+AS19+AT19 -> 22000 | AV19: Paid | AY19: 22000 | AZ19: 0 | BA19: 0 | BD19: =SUM(AW19:BC19) -> 22000 | BE19: =BD19-AU19 -> 0 | BF19: Local | BG19: =AF19/1*5 -> 0
B20: 10 | C20: 43830 | D20: 10000 | E20: =ROUND(_xlfn.DAYS($E$1,C20)/30,0) -> 4 | F20: 147 | G20: 43186 | H20: CT | I20: Shahbaz Khan | J20: Data Analysis | K20: Trainee | L20: Azmeer | M20: HW | N20: ALL | O20: P | P20: =10000+5000+10000+10000 -> 35000 | Q20: =P20/160% -> 21875 | R20: =40/100*Q20 -> 8750 | S20: =10/100*Q20 -> 2187.5 | T20: =10/100*Q20 -> 2187.5 | U20: =Q20+R20+S20+T20 -> 35000 | X20: =P20/$G$3*W20 -> 0 | Y20: 4 | Z20: =P20/$G$3*Y20 -> 7368.4211 | AA20: =P20/$G$3/9 -> 204.67836 | AC20: =AA20*AB20 -> 0 | AD20: =U20+V20+X20-Z20-AC20 -> 27631.579 | AE20: 0 | AF20: 0 | AG20: 0 | AH20: 0 | AI20: =AD20-AE20-AG20-AH20-AF20 -> 27631.579 | AJ20: Meezan Bank Limited | AK20: 01750100943393 | AL20: 42201-3746106-1 | AM20: Ali Osama | AR20: =AI20 -> 27631.579 | AS20: =SUM(AN20:AR20) -> 27631.579 | AU20: =+AS20+AT20 -> 27631.579 | AV20: Paid | AY20: 27632 | AZ20: 0 | BA20: 0 | BD20: =SUM(AW20:BC20) -> 27632 | BE20: =BD20-AU20 -> 0.42105263 | BF20: Local | BG20: =AF20/1*5 -> 0
B21: 4 | C21: 43738 | D21: 5000 | E21: =ROUND(_xlfn.DAYS($E$1,C21)/30,0) -> 7 | F21: 168 | G21: 01 Nov 2020 / 12 Sep 2022 | H21: CT | I21: Ammanullah | J21: Administration | K21: Office Boy | L21: Mubashir | M21: ALL | N21: ALL | O21: P | P21: =25000+5000 -> 30000 | Q21: =P21/160% -> 18750 | R21: =40/100*Q21 -> 7500 | S21: =10/100*Q21 -> 1875 | T21: =10/100*Q21 -> 1875 | U21: =Q21+R21+S21+T21 -> 30000 | X21: =P21/$G$3*W21 -> 0 | Y21: 0 | Z21: =P21/$G$3*Y21 -> 0 | AA21: =P21/$G$3/9 -> 175.4386 | AC21: =AA21*AB21 -> 0 | AD21: =U21+V21+X21-Z21-AC21 -> 30000 | AE21: 0 | AF21: 0 | AG21: 4000 | AH21: 5000 | AI21: =AD21-AE21-AG21-AH21-AF21 -> 21000 | AJ21: Habib Bank Limited | AK21: 0017-79008173-03 | AL21: 32404-9685630-7 | AM21: Amanullah | AN21: =+AI21 -> 21000 | AS21: =SUM(AN21:AR21) -> 21000 | AU21: =+AS21+AT21 -> 21000 | AV21: Paid | AW21: 21000 | BA21: 0 | BD21: =SUM(AW21:BC21) -> 21000 | BE21: =BD21-AU21 -> 0 | BF21: Local | BG21: =AF21/1*5 -> 0
B22: 5 | C22: 43738 | D22: 5000 | E22: =ROUND(_xlfn.DAYS($E$1,C22)/30,0) -> 7 | F22: 176 | G22: 43298 | H22: CT | I22: Muhammad Irfan | J22: Administration | K22: Office Boy | L22: Mubashir | M22: ALL | N22: ALL | O22: P | P22: =20000+5000+5000 -> 30000 | Q22: =P22/160% -> 18750 | R22: =40/100*Q22 -> 7500 | S22: =10/100*Q22 -> 1875 | T22: =10/100*Q22 -> 1875 | U22: =Q22+R22+S22+T22 -> 30000 | X22: =P22/$G$3*W22 -> 0 | Y22: 0 | Z22: =P22/$G$3*Y22 -> 0 | AA22: =P22/$G$3/9 -> 175.4386 | AC22: =AA22*AB22 -> 0 | AD22: =U22+V22+X22-Z22-AC22 -> 30000 | AE22: 0 | AF22: 0 | AG22: 0 | AH22: 0 | AI22: =AD22-AE22-AG22-AH22-AF22 -> 30000 | AM22: Amanullah | AR22: =+AI22 -> 30000 | AS22: =SUM(AN22:AR22) -> 30000 | AU22: =+AS22+AT22 -> 30000 | AV22: Paid | AY22: 30000 | BA22: 0 | BD22: =SUM(AW22:BC22) -> 30000 | BE22: =BD22-AU22 -> 0 | BF22: Local | BG22: =AF22/1*5 -> 0
B23: 11 | C23: 43830 | D23: 10000 | E23: =ROUND(_xlfn.DAYS($E$1,C23)/30,0) -> 4 | F23: 173 | G23: 43270 | H23: CT | I23: Mohammad Uzair | J23: Data Analysis | K23: Trainee | L23: Azmeer | M23: HW | N23: ALL | O23: P | P23: =15000+10000+10000 -> 35000 | Q23: =P23/160% -> 21875 | R23: =40/100*Q23 -> 8750 | S23: =10/100*Q23 -> 2187.5 | T23: =10/100*Q23 -> 2187.5 | U23: =Q23+R23+S23+T23 -> 35000 | X23: =P23/$G$3*W23 -> 0 | Y23: 0 | Z23: =P23/$G$3*Y23 -> 0 | AA23: =P23/$G$3/9 -> 204.67836 | AC23: =AA23*AB23 -> 0 | AD23: =U23+V23+X23-Z23-AC23 -> 35000 | AE23: 0 | AF23: 0 | AG23: 0 | AH23: 0 | AI23: =AD23-AE23-AG23-AH23-AF23 -> 35000 | AJ23: Habib Bank Limited | AK23: 0017-79009071-03 | AL23: 42201-0578753-5 | AM23: JAHANGIR HUSSAIN | AN23: =AI23 -> 35000 | AS23: =SUM(AN23:AR23) -> 35000 | AU23: =+AS23+AT23 -> 35000 | AV23: Paid | AW23: 35000 | AZ23: 0 | BA23: 0 | BD23: =SUM(AW23:BC23) -> 35000 | BE23: =BD23-AU23 -> 0 | BF23: Local | BG23: =AF23/1*5 -> 0
B24: 12 | C24: 43830 | D24: 10000 | E24: =ROUND(_xlfn.DAYS($E$1,C24)/30,0) -> 4 | F24: 174 | G24: 43277 | H24: CT | I24: Sammad | J24: Data Analysis | K24: Trainee | L24: Azmeer | M24: HW | N24: ALL | O24: P | P24: =15000+10000+10000 -> 35000 | Q24: =P24/160% -> 21875 | R24: =40/100*Q24 -> 8750 | S24: =10/100*Q24 -> 2187.5 | T24: =10/100*Q24 -> 2187.5 | U24: =Q24+R24+S24+T24 -> 35000 | X24: =P24/$G$3*W24 -> 0 | Y24: 0 | Z24: =P24/$G$3*Y24 -> 0 | AA24: =P24/$G$3/9 -> 204.67836 | AC24: =AA24*AB24 -> 0 | AD24: =U24+V24+X24-Z24-AC24 -> 35000 | AE24: 0 | AF24: 0 | AG24: 0 | AH24: 0 | AI24: =AD24-AE24-AG24-AH24-AF24 -> 35000 | AJ24: Habib Bank Limited | AK24: 0017-79008732-03 | AL24: 42201-2352763-3 | AM24: Samad Khan | AN24: =AI24 -> 35000 | AS24: =SUM(AN24:AR24) -> 35000 | AU24: =+AS24+AT24 -> 35000 | AV24: Paid | AW24: 35000 | AZ24: 0 | BA24: 0 | BD24: =SUM(AW24:BC24) -> 35000 | BE24: =BD24-AU24 -> 0 | BF24: Local | BG24: =AF24/1*5 -> 0
B25: 36 | F25: 226 | G25: 43862 | I25: Syed Shabi ul Hasan Zaidi | J25: Sales | K25: International Sales Executive | L25: Wasif Azhar | M25: HW | N25: GIT | O25: NP | P25: =20000+20000 -> 40000 | Q25: =P25/160% -> 25000 | R25: =40/100*Q25 -> 10000 | S25: =10/100*Q25 -> 2500 | T25: =10/100*Q25 -> 2500 | U25: =Q25+R25+S25+T25 -> 40000 | X25: =P25/$G$6*W25 -> 0 | Y25: =2-1 -> 1 | Z25: =P25/$G$6*Y25 -> 1904.7619 | AA25: =P25/$G$6/9 -> 211.64021 | AC25: =AA25*AB25 -> 0 | AD25: =U25+V25+X25-Z25-AC25 -> 38095.238 | AE25: 0 | AG25: 0 | AH25: 0 | AI25: =AD25-AE25-AG25-AH25-AF25 -> 38095.238 | AJ25: Bank Al Habib | AK25: 10680048013966014 | AL25: 42101-5066364-1 | AM25: Syed Shabi Ul Hasan Zaidi | AQ25: =AI25 -> 38095.238 | AS25: =SUM(AN25:AR25) -> 38095.238 | AU25: =+AS25+AT25 -> 38095.238 | AV25: =+AI25-AU25 -> 0 | AZ25: 0 | BA25: 38095 | BD25: =SUM(AW25:BC25) -> 38095 | BE25: =BD25-AU25 -> -0.23809524 | BF25: US
B26: 34 | C26: 43830 | D26: 9000 | E26: =ROUND(_xlfn.DAYS($E$1,C26)/30,0) -> 4 | F26: 187 | G26: 43692 | H26: CT | I26: Nahyan Hussain | J26: Sales | K26: International Sales Executive | L26: Wasif Azhar | M26: HW | N26: GIT | O26: NP | P26: =36000+9000 -> 45000 | Q26: =P26/160% -> 28125 | R26: =40/100*Q26 -> 11250 | S26: =10/100*Q26 -> 2812.5 | T26: =10/100*Q26 -> 2812.5 | U26: =Q26+R26+S26+T26 -> 45000 | X26: =P26/$G$6*W26 -> 0 | Y26: 1 | Z26: =P26/$G$6*Y26 -> 2142.8571 | AA26: =P26/$G$6/9 -> 238.09524 | AB26: =17*0 -> 0 | AC26: =AA26*AB26 -> 0 | AD26: =U26+V26+X26-Z26-AC26 -> 42857.143 | AE26: 0 | AF26: 0 | AG26: 0 | AH26: 0 | AI26: =AD26-AE26-AG26-AH26-AF26 -> 42857.143 | AJ26: Meezan Bank Limited | AK26: 99530105424627 | AL26: 42501-9444333-5 | AM26: Asad Hussain | AQ26: =AI26 -> 42857.143 | AS26: =SUM(AN26:AR26) -> 42857.143 | AU26: =+AS26+AT26 -> 42857.143 | AV26: =+AI26-AU26 -> 0 | AZ26: 0 | BA26: 42857 | BD26: =SUM(AW26:BC26) -> 42857 | BE26: =BD26-AU26 -> -0.14285714 | BF26: US | BG26: =AF26/1*5 -> 0
F27: 22 | G27: 43937 | I27: Shahmeer Shaikh | J27: Production - Design | M27: Portal | N27: Portal | O27: P | P27: 100000 | Q27: =P27/160% -> 62500 | R27: =40/100*Q27 -> 25000 | S27: =10/100*Q27 -> 6250 | T27: =10/100*Q27 -> 6250 | U27: =Q27+R27+S27+T27 -> 100000 | X27: =P27/$G$6*W27 -> 0 | Y27: 6 | Z27: =P27/$G$6*Y27 -> 28571.429 | AA27: =P27/$G$6/9 -> 529.10053 | AC27: =AA27*AB27 -> 0 | AD27: =U27+V27+X27-Z27-AC27 -> 71428.571 | AE27: 0 | AG27: 0 | AH27: 0 | AI27: =AD27-AE27-AG27-AH27-AF27 -> 71428.571 | AJ27: Habib Bank Limited | AK27: 0017-79008990-03 | AL27: 42101-2904934-9 | AM27: Shahmeer Shaikh | AN27: =Master[[#This Row],[Net Pay]] -> 71428.571 | AS27: =SUM(AN27:AR27) -> 71428.571 | AU27: =+AS27+AT27 -> 71428.571 | AV27: =+AI27-AU27 -> 0 | AZ27: 71429 | BA27: 0 | BD27: =SUM(AW27:BC27) -> 71429 | BE27: =BD27-AU27 -> 0.42857143 | BF27: US | BG27: =AF27/1*5 -> 0
B28: 3 | F28: 204 | G28: 43769 | H28: NJ | I28: Abdul Hadi Ravasia | J28: Accounts | K28: Accounts Executive | L28: Farooq Khan | M28: ALL | N28: ALL | O28: NP | P28: 45000 | Q28: =P28/160% -> 28125 | R28: =40/100*Q28 -> 11250 | S28: =10/100*Q28 -> 2812.5 | T28: =10/100*Q28 -> 2812.5 | U28: =Q28+R28+S28+T28 -> 45000 | X28: =P28/$G$3*W28 -> 0 | Y28: 0 | Z28: =P28/$G$3*Y28 -> 0 | AA28: =P28/$G$3/9 -> 263.15789 | AC28: =AA28*AB28 -> 0 | AD28: =U28+V28+X28-Z28-AC28 -> 45000 | AE28: 0 | AF28: 0 | AG28: 10000 | AH28: 0 | AI28: =AD28-AE28-AG28-AH28-AF28 -> 35000 | AJ28: Meezan Bank Limited | AK28: PK88MEZN0099180107164710 | AL28: 42101-0956661-3 | AM28: ABDUL HADI RAVASIA | AQ28: =AI28 -> 35000 | AS28: =SUM(AN28:AR28) -> 35000 | AU28: =+AS28+AT28 -> 35000 | AV28: =+AI28-AU28 -> 0 | AZ28: 0 | BA28: 35000 | BD28: =SUM(AW28:BC28) -> 35000 | BE28: =BD28-AU28 -> 0 | BF28: Local | BG28: =AF28/1*5 -> 0
B29: 29 | C29: 43890 | D29: 15000 | E29: =ROUND(_xlfn.DAYS($E$1,C29)/30,0) -> 2 | F29: 97 | G29: 43481 | H29: CT | I29: Waniya | J29: Sales | K29: Trainee | L29: Husnain | M29: HW | N29: BD | O29: P | P29: =15000+5000+5000+5000+15000 -> 45000 | Q29: =P29/160% -> 28125 | R29: =40/100*Q29 -> 11250 | S29: =10/100*Q29 -> 2812.5 | T29: =10/100*Q29 -> 2812.5 | U29: =Q29+R29+S29+T29 -> 45000 | X29: =P29/$G$4*W29 -> 0 | Y29: 0 | Z29: =P29/$G$4*Y29 -> 0 | AA29: =P29/$G$4/9 -> 250 | AC29: =AA29*AB29 -> 0 | AD29: =U29+V29+X29-Z29-AC29 -> 45000 | AE29: 0 | AF29: 0 | AG29: 0 | AH29: 0 | AI29: =AD29-AE29-AG29-AH29-AF29 -> 45000 | AJ29: Habib Bank Limited | AK29: 0017-79009274-03 | AL29: 42201-9133325-0 | AM29: Wania Qureshi | AN29: =AI29 -> 45000 | AS29: =SUM(AN29:AR29) -> 45000 | AU29: =+AS29+AT29 -> 45000 | AV29: =+AI29-AU29 -> 0 | AZ29: 45000 | BA29: 0 | BD29: =SUM(AW29:BC29) -> 45000 | BE29: =BD29-AU29 -> 0 | BF29: UK | BG29: =AF29/1*5 -> 0
B30: 8 | F30: 223 | G30: 43866 | I30: Arsalan Ahmed | J30: HR | L30: Wahaj Qureshi | M30: ALL | N30: ALL | O30: NP | P30: 50000 | Q30: =P30/160% -> 31250 | R30: =40/100*Q30 -> 12500 | S30: =10/100*Q30 -> 3125 | T30: =10/100*Q30 -> 3125 | U30: =Q30+R30+S30+T30 -> 50000 | X30: =P30/$G$3*W30 -> 0 | Y30: 1 | Z30: =P30/$G$3*Y30 -> 2631.5789 | AA30: =P30/$G$3/9 -> 292.39766 | AC30: =AA30*AB30 -> 0 | AD30: =U30+V30+X30-Z30-AC30 -> 47368.421 | AE30: 0 | AH30: 5000 | AI30: =AD30-AE30-AG30-AH30-AF30 -> 42368.421 | AJ30: Dubai Islamic Bank | AK30: PK30DUIB0000000808360001 | AL30: 42101-6288236-7 | AM30: Arsalan Ahmed | AQ30: =AI30 -> 42368.421 | AS30: =SUM(AN30:AR30) -> 42368.421 | AU30: =+AS30+AT30 -> 42368.421 | AV30: =+AI30-AU30 -> 0 | AZ30: 0 | BA30: 42368 | BD30: =SUM(AW30:BC30) -> 42368 | BE30: =BD30-AU30 -> -0.42105263 | BF30: Local
F31: 164 | I31: Hareem Fatima | J31: HR | L31: Wahaj Qureshi | M31: ALL | N31: ALL | O31: P | P31: 50000 | Q31: =P31/160% -> 31250 | R31: =40/100*Q31 -> 12500 | S31: =10/100*Q31 -> 3125 | T31: =10/100*Q31 -> 3125 | U31: =Q31+R31+S31+T31 -> 50000 | X31: =P31/$G$3*W31 -> 0 | Y31: 16 | Z31: =P31/$G$3*Y31 -> 42105.263 | AA31: =P31/$G$3/9 -> 292.39766 | AC31: =AA31*AB31 -> 0 | AD31: =U31+V31+X31-Z31-AC31 -> 7894.7368 | AE31: 0 | AF31: 250 | AG31: 0 | AH31: 0 | AI31: =AD31-AE31-AG31-AH31-AF31 -> 7644.7368 | AJ31: Habib Bank Limited | AK31: 0017-79009306-03 | AL31: 42201-75434755-2 | AM31: Hareem Fatima | AN31: =Master[[#This Row],[Net Pay]] -> 7644.7368 | AS31: =SUM(AN31:AR31) -> 7644.7368 | AU31: =+AS31+AT31 -> 7644.7368 | AV31: =+AI31-AU31 -> 0 | BA31: 0 | BB31: 7645 | BD31: =SUM(AW31:BC31) -> 7645 | BE31: =BD31-AU31 -> 0.26315789 | BF31: Local | BG31: =AF31/1*5 -> 1250
B32: 20 | F32: 149 | G32: 43622 | H32: CT | I32: Muhammad Yousuf | J32: Marketing - SEO | K32: SEO Manager | L32: Umair Kaim Khani | M32: HW | N32: ALL | O32: NP | P32: 50000 | Q32: =P32/160% -> 31250 | R32: =40/100*Q32 -> 12500 | S32: =10/100*Q32 -> 3125 | T32: =10/100*Q32 -> 3125 | U32: =Q32+R32+S32+T32 -> 50000 | X32: =P32/$G$3*W32 -> 0 | Y32: 0 | Z32: =P32/$G$3*Y32 -> 0 | AA32: =P32/$G$3/9 -> 292.39766 | AC32: =AA32*AB32 -> 0 | AD32: =U32+V32+X32-Z32-AC32 -> 50000 | AE32: 0 | AF32: 0 | AG32: 0 | AH32: 0 | AI32: =AD32-AE32-AG32-AH32-AF32 -> 50000 | AJ32: Habib Bank Limited | AK32: 2443-79014079-03 | AL32: 42101-4708804-9 | AM32: Muhammad yousuf | AN32: =Master[[#This Row],[Net Pay]] -> 50000 | AS32: =SUM(AN32:AR32) -> 50000 | AU32: =+AS32+AT32 -> 50000 | AV32: =+AI32-AU32 -> 0 | AZ32: 50000 | BA32: 0 | BD32: =SUM(AW32:BC32) -> 50000 | BE32: =BD32-AU32 -> 0 | BF32: Local | BG32: =AF32/1*5 -> 0
B33: 25 | C33: 43708 | D33: 15000 | E33: =ROUND(_xlfn.DAYS($E$1,C33)/30,0) -> 8 | F33: 113 | G33: 43109 | H33: CT | I33: Affan Khan | J33: Procurement | K33: Procurrement Executive | L33: Khawaja | M33: HW | N33: BD | O33: P | P33: =15000+5000+5000+10000+15000 -> 50000 | Q33: =P33/160% -> 31250 | R33: =40/100*Q33 -> 12500 | S33: =10/100*Q33 -> 3125 | T33: =10/100*Q33 -> 3125 | U33: =Q33+R33+S33+T33 -> 50000 | X33: =P33/$G$4*W33 -> 0 | Y33: 0 | Z33: =P33/$G$4*Y33 -> 0 | AA33: =P33/$G$4/9 -> 277.77778 | AC33: =AA33*AB33 -> 0 | AD33: =U33+V33+X33-Z33-AC33 -> 50000 | AE33: 0 | AF33: 0 | AG33: 0 | AH33: 0 | AI33: =AD33-AE33-AG33-AH33-AF33 -> 50000 | AJ33: Habib Bank Limited | AK33: 0017-79008738-03 | AL33: 42101-4961812-5 | AM33: AFFAN KHAN | AN33: =AI33 -> 50000 | AS33: =SUM(AN33:AR33) -> 50000 | AU33: =+AS33+AT33 -> 50000 | AV33: =+AI33-AU33 -> 0 | AZ33: 50000 | BA33: 0 | BD33: =SUM(AW33:BC33) -> 50000 | BE33: =BD33-AU33 -> 0 | BF33: UK | BG33: =AF33/1*5 -> 0
B34: 33 | C34: 43708 | D34: 10000 | E34: =ROUND(_xlfn.DAYS($E$1,C34)/30,0) -> 8 | F34: 155 | G34: 43207 | H34: CT | I34: Syed Sumair Hussain | J34: Sales | K34: International Sales Executive | L34: Wasif Azhar | M34: HW | N34: GIT | O34: P | P34: =40000+10000 -> 50000 | Q34: =P34/160% -> 31250 | R34: =40/100*Q34 -> 12500 | S34: =10/100*Q34 -> 3125 | T34: =10/100*Q34 -> 3125 | U34: =Q34+R34+S34+T34 -> 50000 | X34: =P34/$G$6*W34 -> 0 | Y34: 0 | Z34: =P34/$G$6*Y34 -> 0 | AA34: =P34/$G$6/9 -> 264.55026 | AC34: =AA34*AB34 -> 0 | AD34: =U34+V34+X34-Z34-AC34 -> 50000 | AE34: 0 | AF34: 0 | AG34: 0 | AH34: 0 | AI34: =AD34-AE34-AG34-AH34-AF34 -> 50000 | AJ34: Habib Bank Limited | AK34: 0017-79008896-03 | AL34: 42201-9040498-9 | AM34: Syed Sumair | AN34: =AI34 -> 50000 | AS34: =SUM(AN34:AR34) -> 50000 | AU34: =+AS34+AT34 -> 50000 | AV34: =+AI34-AU34 -> 0 | AZ34: 50000 | BA34: 0 | BD34: =SUM(AW34:BC34) -> 50000 | BE34: =BD34-AU34 -> 0 | BF34: US | BG34: =AF34/1*5 -> 0
B35: 39 | C35: 43830 | D35: 15000 | E35: =ROUND(_xlfn.DAYS($E$1,C35)/30,0) -> 4 | F35: 150 | G35: 43186 | H35: CT | I35: Humayoun Khan | J35: Procurement | K35: Procurement Executive | L35: Nadeem Akhtar | M35: HW | N35: GIT | O35: P | P35: =15000+10000+10000+15000 -> 50000 | Q35: =P35/160% -> 31250 | R35: =40/100*Q35 -> 12500 | S35: =10/100*Q35 -> 3125 | T35: =10/100*Q35 -> 3125 | U35: =Q35+R35+S35+T35 -> 50000 | X35: =P35/$G$4*W35 -> 0 | Y35: 0 | Z35: =P35/$G$4*Y35 -> 0 | AA35: =P35/$G$4/9 -> 277.77778 | AC35: =AA35*AB35 -> 0 | AD35: =U35+V35+X35-Z35-AC35 -> 50000 | AE35: 0 | AF35: 0 | AG35: 0 | AH35: 0 | AI35: =AD35-AE35-AG35-AH35-AF35 -> 50000 | AJ35: Habib Bank Limited | AK35: 0017-79008735-03 | AL35: 44101-9793357-1 | AM35: HUMAYOUN KHAN | AN35: =AI35 -> 50000 | AS35: =SUM(AN35:AR35) -> 50000 | AU35: =+AS35+AT35 -> 50000 | AV35: =+AI35-AU35 -> 0 | AZ35: 50000 | BA35: 0 | BD35: =SUM(AW35:BC35) -> 50000 | BE35: =BD35-AU35 -> 0 | BF35: UK | BG35: =AF35/1*5 -> 0
B36: 19 | C36: 43646 | D36: 20000 | E36: =ROUND(_xlfn.DAYS($E$1,C36)/30,0) -> 10 | F36: 26 | G36: 42601 | H36: CT | I36: Azmeer Sheikh | J36: Data Analysis | K36: Trainee | L36: Umair Kaim Khani | M36: HW | N36: ALL | O36: P | P36: 60000 | Q36: =P36/160% -> 37500 | R36: =40/100*Q36 -> 15000 | S36: =10/100*Q36 -> 3750 | T36: =10/100*Q36 -> 3750 | U36: =Q36+R36+S36+T36 -> 60000 | X36: =P36/$G$3*W36 -> 0 | Y36: 0 | Z36: =P36/$G$3*Y36 -> 0 | AA36: =P36/$G$3/9 -> 350.87719 | AC36: =AA36*AB36 -> 0 | AD36: =U36+V36+X36-Z36-AC36 -> 60000 | AE36: 0 | AF36: 0 | AG36: 0 | AH36: 5000 | AI36: =AD36-AE36-AG36-AH36-AF36 -> 55000 | AJ36: Habib Bank Limited | AK36: 0017-79009066-03 | AL36: 42101-2818484-9 | AM36: AZMEER SHAIKH | AN36: =AI36 -> 55000 | AS36: =SUM(AN36:AR36) -> 55000 | AU36: =+AS36+AT36 -> 55000 | AV36: =+AI36-AU36 -> 0 | AZ36: 55000 | BA36: 0 | BD36: =SUM(AW36:BC36) -> 55000 | BE36: =BD36-AU36 -> 0 | BF36: Local | BG36: =AF36/1*5 -> 0
B37: 38 | C37: 43830 | D37: 15000 | E37: =ROUND(_xlfn.DAYS($E$1,C37)/30,0) -> 4 | F37: 8 | G37: 42308 | H37: CT | I37: Khawar Qureshi | J37: Procurement | K37: Procurement Executive | L37: Nadeem Akhtar | M37: HW | N37: ITN | O37: P | P37: =50000+15000 -> 65000 | Q37: =P37/160% -> 40625 | R37: =40/100*Q37 -> 16250 | S37: =10/100*Q37 -> 4062.5 | T37: =10/100*Q37 -> 4062.5 | U37: =Q37+R37+S37+T37 -> 65000 | X37: =P37/$G$4*W37 -> 0 | Y37: 0 | Z37: =P37/$G$4*Y37 -> 0 | AA37: =P37/$G$4/9 -> 361.11111 | AC37: =AA37*AB37 -> 0 | AD37: =U37+V37+X37-Z37-AC37 -> 65000 | AE37: 0 | AF37: 250 | AG37: 0 | AH37: 0 | AI37: =AD37-AE37-AG37-AH37-AF37 -> 64750 | AJ37: Habib Bank Limited | AK37: 0017-79008521-03 | AL37: 42201-8365639-3 | AM37: Muhammad Khawar | AN37: =AI37 -> 64750 | AS37: =SUM(AN37:AR37) -> 64750 | AU37: =+AS37+AT37 -> 64750 | AV37: =+AI37-AU37 -> 0 | AZ37: 64750 | BA37: 0 | BD37: =SUM(AW37:BC37) -> 64750 | BE37: =BD37-AU37 -> 0 | BF37: UK | BG37: =AF37/1*5 -> 1250
B38: 28 | C38: 43616 | D38: 35000 | E38: =ROUND(_xlfn.DAYS($E$1,C38)/30,0) -> 11 | F38: 107 | G38: 43508 | H38: CT | I38: Hussnain ali farooqi | J38: Sales | K38: International Sales Executive | L38: Wahaj Qureshi | M38: HW | N38: BD | O38: P | P38: =70000-35000+35000 -> 70000 | Q38: =P38/160% -> 43750 | R38: =40/100*Q38 -> 17500 | S38: =10/100*Q38 -> 4375 | T38: =10/100*Q38 -> 4375 | U38: =Q38+R38+S38+T38 -> 70000 | X38: =P38/$G$4*W38 -> 0 | Y38: 0 | Z38: =P38/$G$4*Y38 -> 0 | AA38: =P38/$G$4/9 -> 388.88889 | AC38: =AA38*AB38 -> 0 | AD38: =U38+V38+X38-Z38-AC38 -> 70000 | AE38: 241.2 | AF38: 0 | AG38: 0 | AH38: 0 | AI38: =AD38-AE38-AG38-AH38-AF38 -> 69758.8 | AJ38: Habib Bank Limited | AK38: 0017-79009306-03 | AL38: 31304-0957356-1 | AM38: Hareem Fatima | AN38: =AI38 -> 69758.8 | AS38: =SUM(AN38:AR38) -> 69758.8 | AU38: =+AS38+AT38 -> 69758.8 | AV38: =+AI38-AU38 -> 0 | AZ38: 69759 | BA38: 0 | BD38: =SUM(AW38:BC38) -> 69759 | BE38: =BD38-AU38 -> 0.2 | BF38: UK | BG38: =AF38/1*5 -> 0
B39: 9 | C39: 43861 | D39: 15000 | E39: =ROUND(_xlfn.DAYS($E$1,C39)/30,0) -> 3 | F39: 135 | G39: 43524 | H39: CT | I39: Farhad Muhammad Khan | J39: IT | K39: Support Engineer | L39: Wahaj Qureshi | M39: ALL | N39: ALL | O39: P | P39: =50000+15000+15000 -> 80000 | Q39: =P39/160% -> 50000 | R39: =40/100*Q39 -> 20000 | S39: =10/100*Q39 -> 5000 | T39: =10/100*Q39 -> 5000 | U39: =Q39+R39+S39+T39 -> 80000 | X39: =P39/$G$3*W39 -> 0 | Y39: 0 | Z39: =P39/$G$3*Y39 -> 0 | AA39: =P39/$G$3/9 -> 467.83626 | AC39: =AA39*AB39 -> 0 | AD39: =U39+V39+X39-Z39-AC39 -> 80000 | AE39: 467.8 | AF39: 0 | AG39: 0 | AH39: 0 | AI39: =AD39-AE39-AG39-AH39-AF39 -> 79532.2 | AJ39: Meezan Bank Limited | AK39: PK40MEZN0099090107351285 | AL39: 42401-0634733-9 | AM39: Farhad Muhammad Khan | AQ39: =AI39 -> 79532.2 | AS39: =SUM(AN39:AR39) -> 79532.2 | AU39: =+AS39+AT39 -> 79532.2 | AV39: =+AI39-AU39 -> 0 | AZ39: 0 | BA39: 79532 | BD39: =SUM(AW39:BC39) -> 79532 | BE39: =BD39-AU39 -> -0.2 | BF39: Local | BG39: =AF39/1*5 -> 0
B40: 26 | C40: 43708 | D40: 40000 | E40: =ROUND(_xlfn.DAYS($E$1,C40)/30,0) -> 8 | F40: 133 | G40: 21 | H40: CT | I40: Eraj Khalid | J40: Sales | K40: Sales/CSE | L40: Husnain | M40: HW | N40: BD | O40: P | P40: =20000+10000+10000+40000 -> 80000 | Q40: =P40/160% -> 50000 | R40: =40/100*Q40 -> 20000 | S40: =10/100*Q40 -> 5000 | T40: =10/100*Q40 -> 5000 | U40: =Q40+R40+S40+T40 -> 80000 | X40: =P40/$G$4*W40 -> 0 | Y40: 0 | Z40: =P40/$G$4*Y40 -> 0 | AA40: =P40/$G$4/9 -> 444.44444 | AC40: =AA40*AB40 -> 0 | AD40: =U40+V40+X40-Z40-AC40 -> 80000 | AE40: 487.4 | AF40: 250 | AG40: 0 | AH40: 0 | AI40: =AD40-AE40-AG40-AH40-AF40 -> 79262.6 | AJ40: Habib Bank Limited | AK40: 0017-79008733-03 | AL40: 42201-1039448-6 | AM40: ERAJ KHALID | AN40: =AI40 -> 79262.6 | AS40: =SUM(AN40:AR40) -> 79262.6 | AU40: =+AS40+AT40 -> 79262.6 | AV40: =+AI40-AU40 -> 0 | AZ40: 79263 | BA40: 0 | BD40: =SUM(AW40:BC40) -> 79263 | BE40: =BD40-AU40 -> 0.4 | BF40: UK | BG40: =AF40/1*5 -> 1250
...

Sheet Brandwise Allocation
D2: Gross Salary | E2: Gross salary with Conveyance | F2: Net Gross | G2: Net Pay | H2: EOBI Employers' Contribution | I2: Total Expense
B3: {=_xlfn.UNIQUE(Master[MCS]:Master[BRAND])} -> HW | C3: BNS | D3: =SUMIFS(Master[Gross Salary],Master[MCS],B3,Master[BRAND],C3) -> 130000 | E3: =SUMIFS(Master[Gross salary with Conveyance],Master[MCS],B3,Master[BRAND],C3) -> 130000 | F3: =SUMIFS(Master[Net Gross],Master[MCS],B3,Master[BRAND],C3) -> 130000 | G3: =SUMIFS(Master[Net Pay],Master[MCS],B3,Master[BRAND],C3) -> 128209.75 | H3: =SUMIFS(Master[EOBI Employers'' Contribution],Master[MCS],B3,Master[BRAND],C3) -> 0 | I3: =F3+H3 -> 130000
B4: HW | C4: ALL | D4: =SUMIFS(Master[Gross Salary],Master[MCS],B4,Master[BRAND],C4) -> 570000 | E4: =SUMIFS(Master[Gross salary with Conveyance],Master[MCS],B4,Master[BRAND],C4) -> 645000 | F4: =SUMIFS(Master[Net Gross],Master[MCS],B4,Master[BRAND],C4) -> 592017.54 | G4: =SUMIFS(Master[Net Pay],Master[MCS],B4,Master[BRAND],C4) -> 501977.54 | H4: =SUMIFS(Master[EOBI Employers'' Contribution],Master[MCS],B4,Master[BRAND],C4) -> 1250 | I4: =F4+H4 -> 593267.54
B5: HW | C5: BD | D5: =SUMIFS(Master[Gross Salary],Master[MCS],B5,Master[BRAND],C5) -> 525000 | E5: =SUMIFS(Master[Gross salary with Conveyance],Master[MCS],B5,Master[BRAND],C5) -> 610000 | F5: =SUMIFS(Master[Net Gross],Master[MCS],B5,Master[BRAND],C5) -> 560750 | G5: =SUMIFS(Master[Net Pay],Master[MCS],B5,Master[BRAND],C5) -> 471908.7 | H5: =SUMIFS(Master[EOBI Employers'' Contribution],Master[MCS],B5,Master[BRAND],C5) -> 2500 | I5: =F5+H5 -> 563250
B6: ALL | C6: ALL | D6: =SUMIFS(Master[Gross Salary],Master[MCS],B6,Master[BRAND],C6) -> 657000 | E6: =SUMIFS(Master[Gross salary with Conveyance],Master[MCS],B6,Master[BRAND],C6) -> 657000 | F6: =SUMIFS(Master[Net Gross],Master[MCS],B6,Master[BRAND],C6) -> 612263.16 | G6: =SUMIFS(Master[Net Pay],Master[MCS],B6,Master[BRAND],C6) -> 579238.96 | H6: =SUMIFS(Master[EOBI Employers'' Contribution],Master[MCS],B6,Master[BRAND],C6) -> 3750 | I6: =F6+H6 -> 616013.16
B7: HW | C7: GIT | D7: =SUMIFS(Master[Gross Salary],Master[MCS],B7,Master[BRAND],C7) -> 495000 | E7: =SUMIFS(Master[Gross salary with Conveyance],Master[MCS],B7,Master[BRAND],C7) -> 495000 | F7: =SUMIFS(Master[Net Gross],Master[MCS],B7,Master[BRAND],C7) -> 490952.38 | G7: =SUMIFS(Master[Net Pay],Master[MCS],B7,Master[BRAND],C7) -> 479906.53 | H7: =SUMIFS(Master[EOBI Employers'' Contribution],Master[MCS],B7,Master[BRAND],C7) -> 1250 | I7: =F7+H7 -> 492202.38
B8: Portal | C8: Portal | D8: =SUMIFS(Master[Gross Salary],Master[MCS],B8,Master[BRAND],C8) -> 275000 | E8: =SUMIFS(Master[Gross salary with Conveyance],Master[MCS],B8,Master[BRAND],C8) -> 275000 | F8: =SUMIFS(Master[Net Gross],Master[MCS],B8,Master[BRAND],C8) -> 246428.57 | G8: =SUMIFS(Master[Net Pay],Master[MCS],B8,Master[BRAND],C8) -> 246428.57 | H8: =SUMIFS(Master[EOBI Employers'' Contribution],Master[MCS],B8,Master[BRAND],C8) -> 0 | I8: =F8+H8 -> 246428.57
B9: HW | C9: ITN | D9: =SUMIFS(Master[Gross Salary],Master[MCS],B9,Master[BRAND],C9) -> 560000 | E9: =SUMIFS(Master[Gross salary with Conveyance],Master[MCS],B9,Master[BRAND],C9) -> 560000 | F9: =SUMIFS(Master[Net Gross],Master[MCS],B9,Master[BRAND],C9) -> 560000 | G9: =SUMIFS(Master[Net Pay],Master[MCS],B9,Master[BRAND],C9) -> 534382 | H9: =SUMIFS(Master[EOBI Employers'' Contribution],Master[MCS],B9,Master[BRAND],C9) -> 3750 | I9: =F9+H9 -> 563750
D10: =SUMIFS(Master[Gross Salary],Master[MCS],B10,Master[BRAND],C10) -> 0 | E10: =SUMIFS(Master[Gross salary with Conveyance],Master[MCS],B10,Master[BRAND],C10) -> 0 | F10: =SUMIFS(Master[Net Gross],Master[MCS],B10,Master[BRAND],C10) -> 0 | G10: =SUMIFS(Master[Net Pay],Master[MCS],B10,Master[BRAND],C10) -> 0 | H10: =SUMIFS(Master[EOBI Employers'' Contribution],Master[MCS],B10,Master[BRAND],C10) -> 0 | I10: =F10+H10 -> 0
D11: =SUMIFS(Master[Gross Salary],Master[MCS],B11,Master[BRAND],C11) -> 0 | E11: =SUMIFS(Master[Gross salary with Conveyance],Master[MCS],B11,Master[BRAND],C11) -> 0 | F11: =SUMIFS(Master[Net Gross],Master[MCS],B11,Master[BRAND],C11) -> 0 | G11: =SUMIFS(Master[Net Pay],Master[MCS],B11,Master[BRAND],C11) -> 0 | H11: =SUMIFS(Master[EOBI Employers'' Contribution],Master[MCS],B11,Master[BRAND],C11) -> 0 | I11: =F11+H11 -> 0
D12: =SUMIFS(Master[Gross Salary],Master[MCS],B12,Master[BRAND],C12) -> 0 | E12: =SUMIFS(Master[Gross salary with Conveyance],Master[MCS],B12,Master[BRAND],C12) -> 0 | F12: =SUMIFS(Master[Net Gross],Master[MCS],B12,Master[BRAND],C12) -> 0 | G12: =SUMIFS(Master[Net Pay],Master[MCS],B12,Master[BRAND],C12) -> 0 | H12: =SUMIFS(Master[EOBI Employers'' Contribution],Master[MCS],B12,Master[BRAND],C12) -> 0 | I12: =F12+H12 -> 0 | K12: 127640
K13: 183000
D14: =SUM(D3:D13) -> 3212000 | E14: =SUM(E3:E13) -> 3372000 | F14: =SUM(F3:F13) -> 3192411.7 | G14: =SUM(G3:G13) -> 2942052.1 | H14: =SUM(H3:H13) -> 12500 | I14: =SUM(I3:I13) -> 3204911.7 | K14: =5000*276 -> 1380000
D15: =SUM(Master[Gross Salary]) -> 3212000 | E15: =SUM(Master[Gross salary with Conveyance]) -> 3372000 | F15: =SUM(Master[Net Gross]) -> 3192411.7 | G15: =SUM(Master[Net Pay]) -> 2942052.1 | H15: =SUM(Master[EOBI Employers'' Contribution]) -> 12500 | K15: =7000*345 -> 2415000
D16: =+D14-D15 -> 0 | E16: =+E14-E15 -> 0 | F16: =+F14-F15 -> 0 | G16: =+G14-G15 -> 0 | H16: =+H14-H15 -> 0 | K16: =SUM(K12:K15) -> 4105640
G17: 1953000 | K17: -2754533
G18: =+G14-G17 -> 989052.05
D20: Direct | E20: Indirect | F20: Shared | G20: Total | K20: -200000
K21: =-751634-200000 -> -951634
B22: Bulk Devices UK | D22: =I5 -> 563250 | E22: =$I$4/2 -> 296633.77 | F22: =$I$6/3 -> 205337.72 | G22: =SUM(D22:F22) -> 1065221.5
B23: ITNHub Ltd | D23: =I9 -> 563750 | E23: 0 | F23: =$I$6/3 -> 205337.72 | G23: =SUM(D23:F23) -> 769087.72
B24: Gracile IT | D24: =I7 -> 492202.38 | E24: =$I$4/2 -> 296633.77 | F24: =$I$6/3 -> 205337.72 | G24: =SUM(D24:F24) -> 994173.87
B25: Blitz Network Solutions | D25: =I3 -> 130000 | E25: 0 | G25: =SUM(D25:F25) -> 130000 | K25: =SUM(K16:K24) -> 199473
B26: Design Portal | D26: =I10 -> 0 | E26: =I8 -> 246428.57 | G26: =SUM(D26:F26) -> 246428.57
D28: =SUM(D22:D27) -> 1749202.4 | E28: =SUM(E22:E27) -> 839696.12 | F28: =SUM(F22:F27) -> 616013.16 | G28: =SUM(G22:G27) -> 3204911.7 | H28: =G28-I14 -> 0
I45: Shahmeer Shaikh
I47: 40000 | J47: 10 | K47: =I47/21*J47 -> 19047.619
I48: 100000 | J48: 11 | K48: =I48/21*J48 -> 52380.952
K50: =SUM(K47:K49) -> 71428.571
K51: 100000
K52: =+K50-K51 -> -28571.429

Sheet <35K
A1: BSD Technologies - Salaries <= 35K | H1: HIDE | I1: Increment | J1: Forex | K1: 280 | Q1: HIDE | R1: HIDE | S1: HIDE | T1: HIDE | AG1: 2000
A2: Payroll | I2: New Joining
A3: Wkg Days (Local) | G3: 22 | I3: Last Month | AJ3: 1.1666667
A4: Wkg Days (Hardware UK) | G4: 22 | I4: Probation | Q4: =COLUMN()-2 -> 15 | R4: =COLUMN()-2 -> 16 | S4: =COLUMN()-2 -> 17 | T4: =COLUMN()-2 -> 18 | AJ4: =COLUMN()-2 -> 34 | AK4: =COLUMN()-2 -> 35 | AL4: =COLUMN()-2 -> 36
A5: Wkg Days (Design US) | G5: 21
A6: Wkg Days (Hardware US) | G6: 21 | J6: =COLUMN()-5 -> 5 | K6: =COLUMN()-5 -> 6 | M6: =COLUMN()-5 -> 8 | N6: =COLUMN()-5 -> 9 | O6: =COLUMN()-5 -> 10 | P6: =COLUMN()-5 -> 11 | Q6: =COLUMN()-5 -> 12 | R6: =COLUMN()-5 -> 13 | S6: =COLUMN()-5 -> 14 | T6: =COLUMN()-5 -> 15 | ... AL6: =COLUMN()-5 -> 33
B7: Sr.No | C7: date of last increment | D7: last incremnet | E7: # Months Since Last Increment | F7: Emp Code | G7: DOJ (DD/MM/Y) | H7: CURRENT STATUS | I7: Employee Name (CNIC) | J7: Department | K7: Designation | L7: Reporting Manager | M7: MCS | N7: BRAND | O7: Status | P7: Gross Salary | Q7: Basic Salary | R7: H.Rent All | S7: Ut. All | T7: Conv. All | U7: Gross salary | V7: Bonus/Incentive/ Reimbursemet | W7: No.Extra Days | X7: Amount Ex. Days | Y7: DISAPPROVED Absent Days | Z7: Deduction absent Days | AA7: Hourly Rate | AB7: No. of Ded Hours | AC7: Ded Amt Hrs | AD7: Net Gross | AE7: Tax | AF7: EOBI | AG7: Advance | AH7: Loan | AI7: Net Pay | AJ7: Bank Name | AK7: AC Number | AL7: CNIC | AM7: Account Title | AN7: HBL | AO7: Samba | AP7: Cheque | AQ7: IBFT | AR7: Cash | AS7: Payments | AT7: Hold | AU7: Total
B8: {=_xlfn._xlws.FILTER(Master!B8:AU28,Master!U8:U28<=30000,"")} -> 49 | C8: 0 | D8: 0 | E8: 0 | F8: 701 | G8: 43684 | H8: CT | I8: Usman Amin | J8: Sales | K8: International Sales Executive | L8: Umer Shahjahan | M8: HW | N8: BNS | O8: NP | P8: 0 | Q8: 0 | R8: 0 | S8: 0 | T8: 0 | U8: 0 | V8: 0 | W8: 0 | X8: 0 | Y8: 0 | Z8: 0 | AA8: 0 | AB8: 0 | AC8: 0 | AD8: 0 | AE8: 0 | AF8: 0 | AG8: 0 | AH8: 0 | AI8: 0 | AJ8: Habib Bank Limited | AK8: 0445-79012790-99 | AL8: 35202-7785641-9 | AM8: Muhammad ADA | AN8: 0 | AO8: 0 | AP8: 0 | AQ8: 0 | AR8: 0 | AS8: 0 | AT8: 0 | AU8: 0 | AW8: 144 | AX8: =+F8-AW8 -> 557
B9: 15 | C9: 0 | D9: 0 | E9: 0 | F9: 191 | G9: 43788 | H9: NJ | I9: Usman | J9: Data Analysis | K9: Trainee | L9: Azmeer | M9: HW | N9: ALL | O9: NP | P9: 15000 | Q9: 9375 | R9: 3750 | S9: 937.5 | T9: 937.5 | U9: 15000 | V9: 0 | W9: 0 | X9: 0 | Y9: 14 | Z9: 11052.632 | AA9: 87.719298 | AB9: 0 | AC9: 0 | AD9: 3947.3684 | AE9: 0 | AF9: 0 | AG9: 0 | AH9: 0 | AI9: 3947.3684 | AJ9: 0 | AK9: 0 | AL9: 0 | AM9: Muhammad Khawar | AN9: 0 | AO9: 0 | AP9: 0 | AQ9: 0 | AR9: 3947.3684 | AS9: 3947.3684 | AT9: 0 | AU9: 3947.3684 | AW9: 999 | AX9: =+F9-AW9 -> -808
B10: 0 | C10: 0 | D10: 0 | E10: 0 | F10: 229 | G10: 43942 | H10: 0 | I10: Maham Khan | J10: Sales | K10: International Sales Executive | L10: 0 | M10: HW | N10: BD | O10: NP | P10: 30000 | Q10: 18750 | R10: 7500 | S10: 1875 | T10: 1875 | U10: 30000 | V10: 0 | W10: 0 | X10: 0 | Y10: 13 | Z10: 19500 | AA10: 166.66667 | AB10: 0 | AC10: 0 | AD10: 10500 | AE10: 0 | AF10: 0 | AG10: 0 | AH10: 0 | AI10: 10500 | AJ10: Habib Bank Limited | AK10: PK70HABB0022567901806303 | AL10: 42301-1466430-6 | AM10: Muhammad Ali | AN10: 0 | AO10: 0 | AP10: 0 | AQ10: 0 | AR10: 10500 | AS10: 10500 | AT10: 0 | AU10: 10500 | AW10: 168 | AX10: =+F10-AW10 -> 61
B11: 16 | C11: 0 | D11: 0 | E11: 0 | F11: 224 | G11: 43861 | H11: 0 | I11: Taha Ahmed | J11: Data Analysis | K11: Trainee | L11: Azmeer | M11: HW | N11: ALL | O11: NP | P11: 15000 | Q11: 9375 | R11: 3750 | S11: 937.5 | T11: 937.5 | U11: 15000 | V11: 0 | W11: 0 | X11: 0 | Y11: 0 | Z11: 0 | AA11: 87.719298 | AB11: 0 | AC11: 0 | AD11: 15000 | AE11: 0 | AF11: 0 | AG11: 0 | AH11: 0 | AI11: 15000 | AJ11: MCB Bank | AK11: PK27MUCB0006802010077407 | AL11: 42201-9587377-5 | AM11: Zameer Ahmed Usmani | AN11: 0 | AO11: 0 | AP11: 0 | AQ11: 15000 | AR11: 0 | AS11: 15000 | AT11: 0 | AU11: 15000 | AW11: 176 | AX11: =+F11-AW11 -> 48
B12: 7 | C12: 0 | D12: 0 | E12: 0 | F12: 999 | G12: 43496 | H12: CT | I12: Muhammad Farooq | J12: Administration | K12: Electrician | L12: Mubashir | M12: ALL | N12: ALL | O12: NP | P12: 15000 | Q12: 9375 | R12: 3750 | S12: 937.5 | T12: 937.5 | U12: 15000 | V12: 0 | W12: 0 | X12: 0 | Y12: 0 | Z12: 0 | AA12: 87.719298 | AB12: 0 | AC12: 0 | AD12: 15000 | AE12: 0 | AF12: 0 | AG12: 0 | AH12: 0 | AI12: 15000 | AJ12: Standard Chartered Bank | AK12: 01994613601 | AL12: 0 | AM12: Muhammad Farooq | AN12: 0 | AO12: 0 | AP12: 0 | AQ12: 15000 | AR12: 0 | AS12: 15000 | AT12: 0 | AU12: 15000 | AW12: 164 | AX12: =+F12-AW12 -> 835
B13: 13 | C13: 0 | D13: 0 | E13: 0 | F13: 221 | G13: 43479 | H13: 0 | I13: Abdul Sami Kamali | J13: Data Analysis | K13: Trainee | L13: Azmeer | M13: HW | N13: ALL | O13: NP | P13: 25000 | Q13: 15625 | R13: 6250 | S13: 1562.5 | T13: 1562.5 | U13: 25000 | V13: 0 | W13: 0 | X13: 0 | Y13: 0 | Z13: 0 | AA13: 146.19883 | AB13: 0 | AC13: 0 | AD13: 25000 | AE13: 0 | AF13: 0 | AG13: 0 | AH13: 0 | AI13: 25000 | AJ13: NAYAPAY | AK13: 03313102701 | AL13: 42000-5277363-3 | AM13: Abdul Sami Kamali | AN13: 0 | AO13: 0 | AP13: 0 | AQ13: 25000 | AR13: 0 | AS13: 25000 | AT13: 0 | AU13: 25000 | AW13: 204 | AX13: =+F13-AW13 -> 17
B14: 14 | C14: 0 | D14: 0 | E14: 0 | F14: 225 | G14: 43845 | H14: 0 | I14: Aun Zaidi | J14: Data Analysis | K14: Trainee | L14: Azmeer | M14: HW | N14: ALL | O14: NP | P14: 20000 | Q14: 12500 | R14: 5000 | S14: 1250 | T14: 1250 | U14: 20000 | V14: 0 | W14: 0 | X14: 0 | Y14: 0 | Z14: 0 | AA14: 116.95906 | AB14: 0 | AC14: 0 | AD14: 20000 | AE14: 0 | AF14: 0 | AG14: 0 | AH14: 0 | AI14: 20000 | AJ14: Habib Bank Limited | AK14: 08780017874001 | AL14: 42101-6994069-3 | AM14: SYED AJAZ HUSSAIN ZAIDI | AN14: 20000 | AO14: 0 | AP14: 0 | AQ14: 0 | AR14: 0 | AS14: 20000 | AT14: 0 | AU14: 20000 | AW14: 135 | AX14: =+F14-AW14 -> 90
B15: 22 | C15: 43890 | D15: 10000 | E15: 0 | F15: 202 | G15: 43760 | H15: CT | I15: Muhammad Huzaifa Haleem | J15: Marketing - SEO | K15: SEO Intern | L15: Muhammad Yousuf | M15: HW | N15: ALL | O15: NP | P15: 25000 | Q15: 15625 | R15: 6250 | S15: 1562.5 | T15: 1562.5 | U15: 25000 | V15: 0 | W15: 0 | X15: 0 | Y15: 5 | Z15: 6578.9474 | AA15: 146.19883 | AB15: 15 | AC15: 2192.9825 | AD15: 16228.07 | AE15: 0 | AF15: 0 | AG15: 0 | AH15: 0 | AI15: 16228.07 | AJ15: NAYAPAY | AK15: 03491838351 | AL15: 0 | AM15: Muhammad Huzaifa Haleem | AN15: 0 | AO15: 0 | AP15: 0 | AQ15: 0 | AR15: 0 | AS15: 0 | AT15: 16228.07 | AU15: 16228.07 | AW15: 142 | AX15: =+F15-AW15 -> 60
B16: 23 | C16: 0 | D16: 0 | E16: 0 | F16: 222 | G16: 43861 | H16: 0 | I16: Moin Shaikh | J16: Marketing - SEO | K16: SEO Intern | L16: Muhammad Yousuf | M16: HW | N16: ALL | O16: NP | P16: 20000 | Q16: 12500 | R16: 5000 | S16: 1250 | T16: 1250 | U16: 20000 | V16: 0 | W16: 0 | X16: 0 | Y16: 0 | Z16: 0 | AA16: 116.95906 | AB16: 0 | AC16: 0 | AD16: 20000 | AE16: 0 | AF16: 0 | AG16: 0 | AH16: 0 | AI16: 20000 | AJ16: Meezan Bank Limited | AK16: PK26MEZN0001430109041892 | AL16: 42101-2622969-7 | AM16: MOHAMMAD MOIN UDDIN | AN16: 0 | AO16: 0 | AP16: 0 | AQ16: 20000 | AR16: 0 | AS16: 20000 | AT16: 0 | AU16: 20000 | AW16: 149 | AX16: =+F16-AW16 -> 73
B17: 6 | C17: 43738 | D17: 5000 | E17: 7 | F17: 144 | G17: Apr 2023 | H17: CT | I17: Salman | J17: Administration | K17: Office Boy | L17: Mubashir | M17: ALL | N17: ALL | O17: P | P17: 25000 | Q17: 15625 | R17: 6250 | S17: 1562.5 | T17: 1562.5 | U17: 25000 | V17: 0 | W17: 0 | X17: 0 | Y17: 0 | Z17: 0 | AA17: 146.19883 | AB17: 0 | AC17: 0 | AD17: 25000 | AE17: 0 | AF17: 0 | AG17: 3000 | AH17: 0 | AI17: 22000 | AJ17: Habib Bank Limited | AK17: 0017-79008173-03 | AL17: 0 | AM17: Amanullah | AN17: 0 | AO17: 0 | AP17: 0 | AQ17: 0 | AR17: 22000 | AS17: 22000 | AT17: 0 | AU17: 22000 | AW17: 191 | AX17: =+F17-AW17 -> -47
B18: 4 | C18: 43738 | D18: 5000 | E18: 7 | F18: 168 | G18: 01 Nov 2020 / 12 Sep 2022 | H18: CT | I18: Ammanullah | J18: Administration | K18: Office Boy | L18: Mubashir | M18: ALL | N18: ALL | O18: P | P18: 30000 | Q18: 18750 | R18: 7500 | S18: 1875 | T18: 1875 | U18: 30000 | V18: 0 | W18: 0 | X18: 0 | Y18: 0 | Z18: 0 | AA18: 175.4386 | AB18: 0 | AC18: 0 | AD18: 30000 | AE18: 0 | AF18: 0 | AG18: 4000 | AH18: 5000 | AI18: 21000 | AJ18: Habib Bank Limited | AK18: 0017-79008173-03 | AL18: 32404-9685630-7 | AM18: Amanullah | AN18: 21000 | AO18: 0 | AP18: 0 | AQ18: 0 | AR18: 0 | AS18: 21000 | AT18: 0 | AU18: 21000 | AW18: 210 | AX18: =+F18-AW18 -> -42
B19: 5 | C19: 43738 | D19: 5000 | E19: 7 | F19: 176 | G19: 43298 | H19: CT | I19: Muhammad Irfan | J19: Administration | K19: Office Boy | L19: Mubashir | M19: ALL | N19: ALL | O19: P | P19: 30000 | Q19: 18750 | R19: 7500 | S19: 1875 | T19: 1875 | U19: 30000 | V19: 0 | W19: 0 | X19: 0 | Y19: 0 | Z19: 0 | AA19: 175.4386 | AB19: 0 | AC19: 0 | AD19: 30000 | AE19: 0 | AF19: 0 | AG19: 0 | AH19: 0 | AI19: 30000 | AJ19: 0 | AK19: 0 | AL19: 0 | AM19: Amanullah | AN19: 0 | AO19: 0 | AP19: 0 | AQ19: 0 | AR19: 30000 | AS19: 30000 | AT19: 0 | AU19: 30000 | AW19: 202 | AX19: =+F19-AW19 -> -26
AW20: 250 | AX20: =+F20-AW20 -> -250
AW21: 147 | AX21: =+F21-AW21 -> -147
AW22: 173 | AX22: =+F22-AW22 -> -173
AW23: 174 | AX23: =+F23-AW23 -> -174
AW24: 177 | AX24: =+F24-AW24 -> -177
AW25: 26 | AX25: =+F25-AW25 -> -26
AW26: 189 | AX26: =+F26-AW26 -> -189
AW27: 221 | AX27: =+F27-AW27 -> -221
AW28: 97 | AX28: =+F28-AW28 -> -97
AW29: 113 | AX29: =+F29-AW29 -> -113
AW30: 107 | AX30: =+F30-AW30 -> -107
AW31: 82 | AX31: =+F31-AW31 -> -82
... AW42: 184 | AX42: =+F42-AW42 -> -184
P57: =SUBTOTAL(9,P8:P56) -> 250000 | Q57: =SUBTOTAL(9,Q8:Q56) -> 156250 | R57: =SUBTOTAL(9,R8:R56) -> 62500 | S57: =SUBTOTAL(9,S8:S56) -> 15625 | T57: =SUBTOTAL(9,T8:T56) -> 15625 | U57: =SUBTOTAL(9,U8:U56) -> 250000 | V57: =SUBTOTAL(9,V8:V56) -> 0 | X57: =SUBTOTAL(9,X8:X56) -> 0 | Z57: =SUBTOTAL(9,Z8:Z56) -> 37131.579 | AC57: =SUBTOTAL(9,AC8:AC56) -> 2192.9825 | AD57: =SUBTOTAL(9,AD8:AD56) -> 210675.44 | AE57: =SUBTOTAL(9,AE8:AE56) -> 0 | AF57: =SUBTOTAL(9,AF8:AF56) -> 0 | AG57: =SUBTOTAL(9,AG8:AG56) -> 7000 | AH57: =SUBTOTAL(9,AH8:AH56) -> 5000 | AI57: =SUBTOTAL(9,AI8:AI56) -> 198675.44 | AN57: =SUBTOTAL(9,AN8:AN56) -> 41000 | AO57: =SUBTOTAL(9,AO8:AO56) -> 0 | AP57: =SUBTOTAL(9,AP8:AP56) -> 0 | AQ57: =SUBTOTAL(9,AQ8:AQ56) -> 75000 | AR57: =SUBTOTAL(9,AR8:AR56) -> 66447.368 | AS57: =SUBTOTAL(9,AS8:AS56) -> 182447.37 | AT57: =SUBTOTAL(9,AT8:AT56) -> 16228.07 | AU57: =SUBTOTAL(9,AU8:AU56) -> 198675.44
AU58: =+AU57-AI57 -> 0
AS59: 1429657.2
AS60: -3694 | AT60: Optome
AS61: -4053 | AT61: Transworld Home
AS62: -157400 | AT62: DIB
AS63: =SUM(AS59:AS62) -> 1264510.2 | AT63: Available Balance
AS64: =+AS63-AS57 -> 1082062.9

Sheet Payroll DES Apr24
A1: BSD Technologies (Design Division) | O1: HIDE | Q1: HIDE | R1: HIDE | S1: HIDE | T1: HIDE | AA1: HIDE | AB1: HIDE | AC1: HIDE
A2: Payroll | C2: April | G2: 2024
G4: 2 | H4: 3 | I4: 4 | J4: 5 | K4: 6 | L4: 7 | M4: 8 | N4: 9 | O4: 10 | P4: 11 | Q4: 12 | R4: 13 | S4: 14 | T4: 15 | U4: 16 | V4: 17 | W4: 18 | X4: 19 | Y4: 20 | Z4: 21 | AA4: 22 | AB4: 23 | AC4: 24 | AD4: 25 | AE4: 26 | AF4: 27 | AG4: 28 | AH4: 29 | AI4: 30 | AJ4: 31 | AK4: 32 | AL4: 33 | AM4: 34 | AN4: 35 | AO4: 36 | AP4: 37 | AQ4: 38 | AR4: 39 | AS4: 40 | AT4: 41 | AU4: 42
B5: Sr.No | C5: Emp Code | D5: Incr. Date | E5: Incr. Amount | F5: Incr. Months | G5: DOJ (DD/MM/Y) | H5: CURRENT STATUS | I5: Employee Name (CNIC) | J5: Department | K5: Designation | L5: Reporting Manager | M5: MCS | N5: BRAND | O5: Status | P5: Gross Salary | Q5: Basic Salary | R5: H.Rent All | S5: Ut. All | T5: Conv. All | U5: Gross salary | V5: Bonus/Incentive/Reimbursemet | W5: No.Extra Days | X5: Amount Ex. Days | Y5: DISAPPROVED Absent Days | Z5: Deduction absent Days | AA5: Hourly Rate | AB5: No. of Ded Hours | AC5: Ded Amt Hrs | AD5: Net Gross (PKR) | AE5: Tax | AF5: EOBI | AG5: Advance | AH5: Loan | AI5: Net Pay | AJ5: Bank Name | AK5: AC Number | AL5: CNIC | AM5: Account Title | AN5: HBL | AO5: Samba | AP5: Cheque | AQ5: IBFT | AR5: Cash | AS5: Payments | AT5: Hold | AU5: Total | AW5: FOREX | AX5: Net Gross (USD)
B7: 1 | C7: 22 | D7: =_xlfn.XLOOKUP(C7,Master[Emp Code],Master[date of last increment]) -> 0 | E7: =_xlfn.XLOOKUP(C7,Master[Emp Code],Master[[last incremnet ]]) -> 0 | F7: =_xlfn.XLOOKUP(C7,Master[Emp Code],Master['# Months Since Last Increment]) -> 0 | G7: =VLOOKUP($C7,Master!$F:$AU,G$4,FALSE) -> 43937 | H7: =VLOOKUP($C7,Master!$F:$AU,H$4,FALSE) -> 0 | I7: =VLOOKUP($C7,Master!$F:$AU,I$4,FALSE) -> Shahmeer Shaikh | J7: =VLOOKUP($C7,Master!$F:$AU,J$4,FALSE) -> Production - Design | K7: =VLOOKUP($C7,Master!$F:$AU,K$4,FALSE) -> 0 | L7: =VLOOKUP($C7,Master!$F:$AU,L$4,FALSE) -> 0 | M7: =VLOOKUP($C7,Master!$F:$AU,M$4,FALSE) -> Portal | N7: =VLOOKUP($C7,Master!$F:$AU,N$4,FALSE) -> Portal | ... AK7: =VLOOKUP($C7,Master!$F:$AU,AK$4,FALSE) -> 0017-79008990-03 | AL7: 4220137461061 | AM7: =VLOOKUP($C7,Master!$F:$AU,AM$4,FALSE) -> Shahmeer Shaikh | AN7: =VLOOKUP($C7,Master!$F:$AU,AN$4,FALSE) -> 71428.571 | AO7: =VLOOKUP($C7,Master!$F:$AU,AO$4,FALSE) -> 0 | AP7: =VLOOKUP($C7,Master!$F:$AU,AP$4,FALSE) -> 0 | AQ7: =VLOOKUP($C7,Master!$F:$AU,AQ$4,FALSE) -> 0 | AR7: =VLOOKUP($C7,Master!$F:$AU,AR$4,FALSE) -> 0 | AS7: =VLOOKUP($C7,Master!$F:$AU,AS$4,FALSE) -> 71428.571 | AT7: =VLOOKUP($C7,Master!$F:$AU,AT$4,FALSE) -> 0 | AU7: =VLOOKUP($C7,Master!$F:$AU,AU$4,FALSE) -> 71428.571 | AW7: =+Master!$K$1 -> 276 | AX7: =+AD7/AW7 -> 258.79917 | AY7: =+AD7/AW7 -> 258.79917
B8: 1 | C8: 80 | D8: =_xlfn.XLOOKUP(C8,Master[Emp Code],Master[date of last increment]) -> 0 | E8: =_xlfn.XLOOKUP(C8,Master[Emp Code],Master[[last incremnet ]]) -> 0 | F8: =_xlfn.XLOOKUP(C8,Master[Emp Code],Master['# Months Since Last Increment]) -> 0 | G8: =VLOOKUP($C8,Master!$F:$AU,G$4,FALSE) -> 0 | H8: =VLOOKUP($C8,Master!$F:$AU,H$4,FALSE) -> 0 | I8: =VLOOKUP($C8,Master!$F:$AU,I$4,FALSE) -> Ibtihaj Ali Haider | J8: =VLOOKUP($C8,Master!$F:$AU,J$4,FALSE) -> Sales | K8: =VLOOKUP($C8,Master!$F:$AU,K$4,FALSE) -> 0 | L8: =VLOOKUP($C8,Master!$F:$AU,L$4,FALSE) -> 0 | M8: =VLOOKUP($C8,Master!$F:$AU,M$4,FALSE) -> Portal | N8: =VLOOKUP($C8,Master!$F:$AU,N$4,FALSE) -> Portal | ... AK8: =VLOOKUP($C8,Master!$F:$AU,AK$4,FALSE) -> 0017-79008290-03 | AL8: 4220137461061 | AM8: =VLOOKUP($C8,Master!$F:$AU,AM$4,FALSE) -> Muhammad Ibtehaj Ali Haider | AN8: =VLOOKUP($C8,Master!$F:$AU,AN$4,FALSE) -> 175000 | AO8: =VLOOKUP($C8,Master!$F:$AU,AO$4,FALSE) -> 0 | AP8: =VLOOKUP($C8,Master!$F:$AU,AP$4,FALSE) -> 0 | AQ8: =VLOOKUP($C8,Master!$F:$AU,AQ$4,FALSE) -> 0 | AR8: =VLOOKUP($C8,Master!$F:$AU,AR$4,FALSE) -> 0 | AS8: =VLOOKUP($C8,Master!$F:$AU,AS$4,FALSE) -> 175000 | AT8: =VLOOKUP($C8,Master!$F:$AU,AT$4,FALSE) -> 0 | AU8: =VLOOKUP($C8,Master!$F:$AU,AU$4,FALSE) -> 175000 | AW8: =+Master!$K$1 -> 276 | AX8: =+AD8/AW8 -> 634.05797 | AY8: =+AD8/AW8 -> 634.05797
P11: =SUBTOTAL(9,P7:P10) -> 275000 | Q11: =SUBTOTAL(9,Q7:Q10) -> 171875 | R11: =SUBTOTAL(9,R7:R10) -> 68750 | S11: =SUBTOTAL(9,S7:S10) -> 17187.5 | T11: =SUBTOTAL(9,T7:T10) -> 17187.5 | U11: =SUBTOTAL(9,U7:U10) -> 275000 | V11: =SUBTOTAL(9,V7:V10) -> 0 | X11: =SUBTOTAL(9,X7:X10) -> 0 | Z11: =SUBTOTAL(9,Z7:Z10) -> 28571.429 | AC11: =SUBTOTAL(9,AC7:AC10) -> 0 | AD11: =SUBTOTAL(9,AD7:AD10) -> 246428.57 | AE11: =SUBTOTAL(9,AE7:AE10) -> 0 | AF11: =SUBTOTAL(9,AF7:AF10) -> 0 | AG11: =SUBTOTAL(9,AG7:AG10) -> 0 | AH11: =SUBTOTAL(9,AH7:AH10) -> 0 | AI11: =SUBTOTAL(9,AI7:AI10) -> 246428.57 | AN11: =SUBTOTAL(9,AN7:AN10) -> 246428.57 | AO11: =SUBTOTAL(9,AO7:AO10) -> 0 | AP11: =SUBTOTAL(9,AP7:AP10) -> 0 | AQ11: =SUBTOTAL(9,AQ7:AQ10) -> 0 | AR11: =SUBTOTAL(9,AR7:AR10) -> 0 | AS11: =SUBTOTAL(9,AS7:AS10) -> 246428.57 | AT11: =SUBTOTAL(9,AT7:AT10) -> 0 | AU11: =SUBTOTAL(9,AU7:AU10) -> 246428.57 | AX11: =SUBTOTAL(9,AX7:AX10) -> 892.85714
P16: =SUBTOTAL(9,P13:P15) -> 0 | Q16: =SUBTOTAL(9,Q13:Q15) -> 0 | R16: =SUBTOTAL(9,R13:R15) -> 0 | S16: =SUBTOTAL(9,S13:S15) -> 0 | T16: =SUBTOTAL(9,T13:T15) -> 0 | U16: =SUBTOTAL(9,U13:U15) -> 0 | V16: =SUBTOTAL(9,V13:V15) -> 0 | X16: =SUBTOTAL(9,X13:X14) -> 0 | Z16: =SUBTOTAL(9,Z13:Z15) -> 0 | AD16: =SUBTOTAL(9,AD13:AD15) -> 0 | AE16: =SUBTOTAL(9,AE13:AE15) -> 0 | AF16: =SUBTOTAL(9,AF13:AF15) -> 0 | AG16: =SUBTOTAL(9,AG13:AG15) -> 0 | AH16: =SUBTOTAL(9,AH13:AH15) -> 0 | AI16: =SUBTOTAL(9,AI13:AI15) -> 0 | AJ16: =SUBTOTAL(9,AJ13:AJ15) -> 0 | AK16: =SUBTOTAL(9,AK13:AK15) -> 0 | ... AU16: =SUBTOTAL(9,AU13:AU15) -> 0 | AX16: =SUBTOTAL(9,AX13:AX14) -> 0
P18: =SUBTOTAL(9,P6:P17) -> 275000 | Q18: =SUBTOTAL(9,Q6:Q17) -> 171875 | R18: =SUBTOTAL(9,R6:R17) -> 68750 | S18: =SUBTOTAL(9,S6:S17) -> 17187.5 | T18: =SUBTOTAL(9,T6:T17) -> 17187.5 | U18: =SUBTOTAL(9,U6:U17) -> 275000 | V18: =SUBTOTAL(9,V6:V17) -> 0 | X18: =SUBTOTAL(9,X6:X17) -> 0 | Z18: =SUBTOTAL(9,Z6:Z17) -> 28571.429 | AC18: =SUBTOTAL(9,AC6:AC17) -> 0 | AD18: =SUBTOTAL(9,AD6:AD17) -> 246428.57 | AE18: =SUBTOTAL(9,AE6:AE17) -> 0 | AF18: =SUBTOTAL(9,AF6:AF17) -> 0 | AG18: =SUBTOTAL(9,AG6:AG17) -> 0 | AH18: =SUBTOTAL(9,AH6:AH17) -> 0 | AI18: =SUBTOTAL(9,AI6:AI17) -> 246428.57 | AN18: =SUBTOTAL(9,AN6:AN17) -> 246428.57 | AO18: =SUBTOTAL(9,AO6:AO17) -> 0 | AP18: =SUBTOTAL(9,AP6:AP17) -> 0 | AQ18: =SUBTOTAL(9,AQ6:AQ17) -> 0 | AR18: =SUBTOTAL(9,AR6:AR17) -> 0 | AS18: =SUBTOTAL(9,AS6:AS17) -> 246428.57 | AT18: =SUBTOTAL(9,AT6:AT17) -> 0 | AU18: =SUBTOTAL(9,AU6:AU17) -> 246428.57 | AX18: =SUBTOTAL(9,AX6:AX17) -> 892.85714
M20: PORTAL | N20: Unit - I | P20: =SUMIFS(Master!P$7:P$57,Master!$M$7:$M$57,'Payroll DES Apr24'!$M20,Master!$N$7:$N$57,'Payroll DES Apr24'!$N20) -> 0 | U20: =SUMIFS(Master!U$7:U$57,Master!$M$7:$M$57,'Payroll DES Apr24'!$M20,Master!$N$7:$N$57,'Payroll DES Apr24'!$N20) -> 0 | Z20: =SUMIFS(Master!Z$7:Z$57,Master!$M$7:$M$57,'Payroll DES Apr24'!$M20,Master!$N$7:$N$57,'Payroll DES Apr24'!$N20) -> 0 | AC20: =SUMIFS(Master!AC$7:AC$57,Master!$M$7:$M$57,'Payroll DES Apr24'!$M20,Master!$N$7:$N$57,'Payroll DES Apr24'!$N20) -> 0 | AD20: =SUMIFS(Master!AD$7:AD$57,Master!$M$7:$M$57,'Payroll DES Apr24'!$M20,Master!$N$7:$N$57,'Payroll DES Apr24'!$N20) -> 0 | AE20: =SUMIFS(Master!AE$7:AE$57,Master!$M$7:$M$57,'Payroll DES Apr24'!$M20,Master!$N$7:$N$57,'Payroll DES Apr24'!$N20) -> 0 | AF20: =SUMIFS(Master!AF$7:AF$57,Master!$M$7:$M$57,'Payroll DES Apr24'!$M20,Master!$N$7:$N$57,'Payroll DES Apr24'!$N20) -> 0 | AG20: =SUMIFS(Master!AG$7:AG$57,Master!$M$7:$M$57,'Payroll DES Apr24'!$M20,Master!$N$7:$N$57,'Payroll DES Apr24'!$N20) -> 0 | AH20: =SUMIFS(Master!AH$7:AH$57,Master!$M$7:$M$57,'Payroll DES Apr24'!$M20,Master!$N$7:$N$57,'Payroll DES Apr24'!$N20) -> 0 | AI20: =SUMIFS(Master!AI$7:AI$57,Master!$M$7:$M$57,'Payroll DES Apr24'!$M20,Master!$N$7:$N$57,'Payroll DES Apr24'!$N20) -> 0 | AN20: =SUMIFS(Master!AN$7:AN$57,Master!$M$7:$M$57,'Payroll DES Apr24'!$M20,Master!$N$7:$N$57,'Payroll DES Apr24'!$N20) -> 0 | AO20: =SUMIFS(Master!AO$7:AO$57,Master!$M$7:$M$57,'Payroll DES Apr24'!$M20,Master!$N$7:$N$57,'Payroll DES Apr24'!$N20) -> 0 | AP20: =SUMIFS(Master!AP$7:AP$57,Master!$M$7:$M$57,'Payroll DES Apr24'!$M20,Master!$N$7:$N$57,'Payroll DES Apr24'!$N20) -> 0 | AQ20: =SUMIFS(Master!AQ$7:AQ$57,Master!$M$7:$M$57,'Payroll DES Apr24'!$M20,Master!$N$7:$N$57,'Payroll DES Apr24'!$N20) -> 0 | AR20: =SUMIFS(Master!AR$7:AR$57,Master!$M$7:$M$57,'Payroll DES Apr24'!$M20,Master!$N$7:$N$57,'Payroll DES Apr24'!$N20) -> 0 | AS20: =SUMIFS(Master!AS$7:AS$57,Master!$M$7:$M$57,'Payroll DES Apr24'!$M20,Master!$N$7:$N$57,'Payroll DES Apr24'!$N20) -> 0 | AT20: =SUMIFS(Master!AT$7:AT$57,Master!$M$7:$M$57,'Payroll DES Apr24'!$M20,Master!$N$7:$N$57,'Payroll DES Apr24'!$N20) -> 0 | AU20: =SUMIFS(Master!AU$7:AU$57,Master!$M$7:$M$57,'Payroll DES Apr24'!$M20,Master!$N$7:$N$57,'Payroll DES Apr24'!$N20) -> 0
